Workbook

Sheet Product backlog
A1: ID | B1: Component | C1: Component describe | D1: Epic | E1: Epic describe | F1: Story | G1: Story description | H1: Story point | I1: Priority | J1: Sprint | K1: Release | L1: Status | M1: Start date | N1: End date | O1: Attach link
A2: =row()-1 -> 1 | B2: Nhập kho | C2: Tiếp nhận order từ SAP, điều phối vận hành tại kho thông qua task, kiểm soát tiến độ theo SLA/KPI, cập nhật tồn kho và đồng bộ trạng thái về SAP. | D2: Luồng nhập mua mới | E2: Quy trình xử lý từ khi SAP đồng bộ order về AIWS đến khi kho hoàn thành task và đồng bộ trạng thái ngược về SAP. | F2: Danh sách lệnh nhập | G2: Quản lý/xử lý nghiệp vụ danh sách lệnh nhập theo quyền, trạng thái, processProfile và rule tích hợp đã cấu hình. | J2: sprint 1 | K2: V1.0.0 | L2: developing | M2: 46235 | N2: 46249
A3: =row()-1 -> 2 | B3: Nhập kho | C3: Tiếp nhận order từ SAP, điều phối vận hành tại kho thông qua task, kiểm soát tiến độ theo SLA/KPI, cập nhật tồn kho và đồng bộ trạng thái về SAP. | D3: Luồng nhập mua mới | E3: Quy trình xử lý từ khi SAP đồng bộ order về AIWS đến khi kho hoàn thành task và đồng bộ trạng thái ngược về SAP. | F3: Xem chi tiết lệnh nhập - Tab Thông tin hàng hóa | G3: Quản lý/xử lý nghiệp vụ xem chi tiết lệnh nhập theo quyền, trạng thái, processProfile và rule tích hợp đã cấu hình. | J3: sprint 1 | K3: V1.0.0 | L3: developing | M3: 46235 | N3: 46249
A4: =row()-1 -> 3 | B4: Nhập kho | C4: Tiếp nhận order từ SAP, điều phối vận hành tại kho thông qua task, kiểm soát tiến độ theo SLA/KPI, cập nhật tồn kho và đồng bộ trạng thái về SAP. | D4: Luồng nhập mua mới | E4: Quy trình xử lý từ khi SAP đồng bộ order về AIWS đến khi kho hoàn thành task và đồng bộ trạng thái ngược về SAP. | F4: Xem chi tiết lệnh nhập - Tab Chứng từ | G4: Quản lý/xử lý nghiệp vụ tab chứng từ theo quyền, trạng thái, processProfile và rule tích hợp đã cấu hình. | J4: sprint 1 | K4: V1.0.0 | L4: developing | M4: 46235 | N4: 46249
A5: =row()-1 -> 4 | B5: Nhập kho | C5: Tiếp nhận order từ SAP, điều phối vận hành tại kho thông qua task, kiểm soát tiến độ theo SLA/KPI, cập nhật tồn kho và đồng bộ trạng thái về SAP. | D5: Luồng nhập mua mới | E5: Quy trình xử lý từ khi SAP đồng bộ order về AIWS đến khi kho hoàn thành task và đồng bộ trạng thái ngược về SAP. | F5: Xem chi tiết lệnh nhập - Tab Task | G5: Quản lý/xử lý nghiệp vụ tab Task theo quyền, trạng thái, processProfile và rule tích hợp đã cấu hình. | J5: sprint 1 | K5: V1.0.0 | L5: developing | M5: 46235 | N5: 46249
A6: =row()-1 -> 5 | B6: Nhập kho | C6: Tiếp nhận order từ SAP, điều phối vận hành tại kho thông qua task, kiểm soát tiến độ theo SLA/KPI, cập nhật tồn kho và đồng bộ trạng thái về SAP. | D6: Luồng nhập mua mới | E6: Quy trình xử lý từ khi SAP đồng bộ order về AIWS đến khi kho hoàn thành task và đồng bộ trạng thái ngược về SAP. | F6: Xem chi tiết lệnh nhập - Tab Kết quả KCS | G6: Quản lý/xử lý nghiệp vụ tab Kết quả KCS theo quyền, trạng thái, processProfile và rule tích hợp đã cấu hình. | J6: sprint 1 | K6: V1.0.0 | L6: developing | M6: 46235 | N6: 46249
A7: =row()-1 -> 6 | B7: Nhập kho | C7: Tiếp nhận order từ SAP, điều phối vận hành tại kho thông qua task, kiểm soát tiến độ theo SLA/KPI, cập nhật tồn kho và đồng bộ trạng thái về SAP. | D7: Luồng nhập mua mới | E7: Quy trình xử lý từ khi SAP đồng bộ order về AIWS đến khi kho hoàn thành task và đồng bộ trạng thái ngược về SAP. | F7: Xem chi tiết lệnh nhập - Tab Vận chuyển | G7: Quản lý/xử lý nghiệp vụ tab Vận chuyển theo quyền, trạng thái, processProfile và rule tích hợp đã cấu hình. | J7: sprint 1 | K7: V1.0.0 | L7: developing | M7: 46235 | N7: 46249
A8: =row()-1 -> 7 | B8: Nhập kho | C8: Tiếp nhận order từ SAP, điều phối vận hành tại kho thông qua task, kiểm soát tiến độ theo SLA/KPI, cập nhật tồn kho và đồng bộ trạng thái về SAP. | D8: Luồng nhập mua mới | E8: Quy trình xử lý từ khi SAP đồng bộ order về AIWS đến khi kho hoàn thành task và đồng bộ trạng thái ngược về SAP. | F8: Xem chi tiết lệnh nhập - Tab Lịch sử | G8: Quản lý/xử lý nghiệp vụ tab lịch sử theo quyền, trạng thái, processProfile và rule tích hợp đã cấu hình. | J8: sprint 1 | K8: V1.0.0 | L8: developing | M8: 46235 | N8: 46249
A9: =row()-1 -> 8 | B9: Nhập kho | C9: Tiếp nhận order từ SAP, điều phối vận hành tại kho thông qua task, kiểm soát tiến độ theo SLA/KPI, cập nhật tồn kho và đồng bộ trạng thái về SAP. | D9: Luồng nhập mua mới | E9: Quy trình xử lý từ khi SAP đồng bộ order về AIWS đến khi kho hoàn thành task và đồng bộ trạng thái ngược về SAP. | F9: [Order] Export Excel | G9: Export danh sách order theo điều kiện tìm kiếm. | J9: sprint 1 | K9: V1.0.0 | L9: developing | M9: 46235 | N9: 46249
A10: =row()-1 -> 9 | B10: Nhập kho | C10: Tiếp nhận order từ SAP, điều phối vận hành tại kho thông qua task, kiểm soát tiến độ theo SLA/KPI, cập nhật tồn kho và đồng bộ trạng thái về SAP. | D10: Luồng nhập mua mới | E10: Quy trình xử lý từ khi SAP đồng bộ order về AIWS đến khi kho hoàn thành task và đồng bộ trạng thái ngược về SAP. | F10: [Order] Tìm kiếm nhanh | G10: Tìm kiếm nhanh order theo mã lệnh. | J10: sprint 1 | K10: V1.0.0 | L10: developing | M10: 46235 | N10: 46249
A11: =row()-1 -> 10 | B11: Nhập kho | C11: Tiếp nhận order từ SAP, điều phối vận hành tại kho thông qua task, kiểm soát tiến độ theo SLA/KPI, cập nhật tồn kho và đồng bộ trạng thái về SAP. | D11: Luồng nhập mua mới | E11: Quy trình xử lý từ khi SAP đồng bộ order về AIWS đến khi kho hoàn thành task và đồng bộ trạng thái ngược về SAP. | F11: [Order] Tìm kiếm nâng cao | G11: Tìm kiếm order theo bộ điều kiện tìm kiếm. | J11: sprint 1 | K11: V1.0.0 | L11: developing | M11: 46235 | N11: 46249
A12: =row()-1 -> 11 | B12: Nhập kho | C12: Tiếp nhận order từ SAP, điều phối vận hành tại kho thông qua task, kiểm soát tiến độ theo SLA/KPI, cập nhật tồn kho và đồng bộ trạng thái về SAP. | D12: Luồng nhập mua mới | E12: Quy trình xử lý từ khi SAP đồng bộ order về AIWS đến khi kho hoàn thành task và đồng bộ trạng thái ngược về SAP. | F12: Danh sách Task | G12: Quản lý/xử lý nghiệp vụ danh sách task nhập kho theo quyền, trạng thái, processProfile và rule tích hợp đã cấu hình. | J12: sprint 1 | K12: V1.0.0 | L12: developing | M12: 46235 | N12: 46249
A13: =row()-1 -> 12 | B13: Nhập kho | C13: Tiếp nhận order từ SAP, điều phối vận hành tại kho thông qua task, kiểm soát tiến độ theo SLA/KPI, cập nhật tồn kho và đồng bộ trạng thái về SAP. | D13: Luồng nhập mua mới | E13: Quy trình xử lý từ khi SAP đồng bộ order về AIWS đến khi kho hoàn thành task và đồng bộ trạng thái ngược về SAP. | F13: [Task] Export Excel | G13: Export danh sách task theo điều kiện tìm kiếm. | J13: sprint 1 | K13: V1.0.0 | L13: developing | M13: 46235 | N13: 46249
... A25: =row()-1 -> 24 | B25: Nhập kho | C25: Tiếp nhận order từ SAP, điều phối vận hành tại kho thông qua task, kiểm soát tiến độ theo SLA/KPI, cập nhật tồn kho và đồng bộ trạng thái về SAP. | D25: Luồng nhập mua mới | E25: Quy trình xử lý từ khi SAP đồng bộ order về AIWS đến khi kho hoàn thành task và đồng bộ trạng thái ngược về SAP. | F25: Đưa vào lưu trữ / Putaway | G25: Quản lý/xử lý nghiệp vụ đưa vào lưu trữ/putaway theo quyền, trạng thái, processProfile và rule tích hợp đã cấu hình. | J25: sprint 1 | K25: V1.0.0 | L25: developing | M25: 46235 | N25: 46249
A26: 25 | B26: Nhập kho | C26: Tiếp nhận order từ SAP, điều phối vận hành tại kho thông qua task, kiểm soát tiến độ theo SLA/KPI, cập nhật tồn kho và đồng bộ trạng thái về SAP. | D26: Luồng nhập mua mới | E26: Quy trình xử lý từ khi SAP đồng bộ order về AIWS đến khi kho hoàn thành task và đồng bộ trạng thái ngược về SAP. | F26: Đồng bộ lệnh nhập kho từ SAP/vERP | G26: SAP đẩy thông tin lệnh nhập sang AIWS để AIWS tạo order nhập và sinh task nghiệp vụ tại kho. | J26: sprint 1 | K26: V1.0.0 | L26: developing | M26: 46235 | N26: 46249
A27: 26 | B27: Nhập kho | C27: Tiếp nhận order từ SAP, điều phối vận hành tại kho thông qua task, kiểm soát tiến độ theo SLA/KPI, cập nhật tồn kho và đồng bộ trạng thái về SAP. | D27: Luồng nhập mua mới | E27: Quy trình xử lý từ khi SAP đồng bộ order về AIWS đến khi kho hoàn thành task và đồng bộ trạng thái ngược về SAP. | F27: Dashboard thống kê lệnh nhập | G27: Hiển thị tổng quan tồn kho, phân bổ tồn, hiệu suất vận hành hệ thống, quản lý lệnh, quản lý tiến độ, quản lý task. | J27: sprint 1 | K27: V1.0.0 | L27: developing | M27: 46235 | N27: 46249
A28: 27 | B28: Nhập kho | C28: Tiếp nhận order từ SAP, điều phối vận hành tại kho thông qua task, kiểm soát tiến độ theo SLA/KPI, cập nhật tồn kho và đồng bộ trạng thái về SAP. | D28: Luồng nhập mua mới | E28: Quy trình xử lý từ khi SAP đồng bộ order về AIWS đến khi kho hoàn thành task và đồng bộ trạng thái ngược về SAP. | F28: Phân công lại người phụ trách công việc | G28: Cho phép người quản lý phân công lại task con hoặc người phụ trách order nếu có quyền. | J28: sprint 1 | K28: V1.0.0 | L28: developing | M28: 46235 | N28: 46249

Sheet Sub-task sprint 1
A1: Type | B1: Summary | C1: Description | D1: Priority | E1: Assignee | F1: Reporter | G1: Story point | H1: Start Date | I1: End Date | J1: Original Estimate | K1: Remaining Estimate | L1: Budget/ULNL ( MM) | M1: Thiết bị VPS | N1: Epic link
A2: Epic | B2: Nhập kho - Luồng nhập mới | C2: Nhập kho - Luồng nhập mới | D2: High | E2: dongnt30 | F2: dongnt30 | G2: 13 | H2: 46235 | I2: 46249 | J2: 80h | K2: 80h | L2: 0
A3: Story | B3: Hoàn thành tài liệu nhập kho. Trong SRS V1.0.0 có mô tả chi tiết API | C3: Hoàn thành tài liệu nhập kho. Trong SRS V1.0.0 có mô tả chi tiết API | D3: High | E3: quantm18 | F3: dongnt30 | G3: 5 | H3: 46235 | I3: 46240 | J3: 32h | K3: 32h | L3: 0
A4: Sub-task | B4: Hoàn thành tài liệu nhập kho. Trong SRS V1.0.0 có mô tả chi tiết API | BA- Update tài liệu và Fix comment lần 1 | C4: Hoàn thành tài liệu nhập kho. Trong SRS V1.0.0 có mô tả chi tiết API | BA- Update tài liệu và Fix comment lần 1 | D4: High | E4: hadd | F4: dongnt30 | G4: 3 | H4: 46235 | I4: 46235 | J4: 8h | K4: 8h | L4: 4417
A5: Sub-task | B5: Hoàn thành tài liệu nhập kho. Trong SRS V1.0.0 có mô tả chi tiết API | BA- Update tài liệu và Fix comment lần 2 | C5: Hoàn thành tài liệu nhập kho. Trong SRS V1.0.0 có mô tả chi tiết API | BA- Update tài liệu và Fix comment lần 2 | D5: High | E5: hadd | F5: dongnt30 | G5: 3 | H5: 46235 | I5: 46235 | J5: 8h | K5: 8h | L5: 4417
A6: Sub-task | B6: Hoàn thành tài liệu nhập kho. Trong SRS V1.0.0 có mô tả chi tiết API | BA - Mô hình hóa yêu cầu nhập kho theo yêu cầu mới | C6: Hoàn thành tài liệu nhập kho. Trong SRS V1.0.0 có mô tả chi tiết API | BA - Mô hình hóa yêu cầu nhập kho theo yêu cầu mới | D6: High | E6: hadd | F6: dongnt30 | G6: 3 | H6: 46235 | I6: 46240 | J6: 32h | K6: 32h | L6: 4417
A7: Sub-task | B7: Hoàn thành tài liệu nhập kho. Trong SRS V1.0.0 có mô tả chi tiết API | BA - Viết đặc tả API (50%) | C7: Hoàn thành tài liệu nhập kho. Trong SRS V1.0.0 có mô tả chi tiết API | BA - Viết đặc tả API (50%) | D7: High | E7: hadd | F7: dongnt30 | G7: 3 | H7: 46237 | I7: 46237 | J7: 8h | K7: 8h | L7: 4417
A8: Story | B8: Nhập kho - Tích hợp hệ thống ngoài | C8: Nhập kho - Tích hợp hệ thống ngoài | D8: High | E8: dongnt30 | F8: dongnt30 | G8: 13 | H8: 46239 | I8: 46241 | J8: 24h | K8: 24h | L8: 0
A9: Sub-task | B9: Nhập kho - Tích hợp hệ thống ngoài | BA- Thống nhất với nghiệp vụ Maping về số lượng Movement type và lệnh nhập kho | C9: Nhập kho - Tích hợp hệ thống ngoài | BA- Thống nhất với nghiệp vụ Maping về số lượng Movement type và lệnh nhập kho | D9: High | E9: hadd | F9: dongnt30 | G9: 2 | H9: 46239 | I9: 46241 | J9: 24h | K9: 24h | L9: 4417
A10: Sub-task | B10: Nhập kho - Tích hợp hệ thống ngoài | BA- Thống nhất về thông tin đồng bộ SAP | C10: Đồng bộ thông tin lệnh nhập (2 chiều) Đồng bộ trạng thái lệnh nhập (2 chiều) Đồng bộ thông tin KCS (2 chiều) | D10: High | E10: hadd | F10: dongnt30 | G10: 5 | H10: 46239 | I10: 46241 | J10: 24h | K10: 24h | L10: 4417
A11: Sub-task | B11: Nhập kho - Tích hợp hệ thống ngoài | BA- Thống nhất về thông tin đồng bộ SAP | C11: Đồng bộ thông tin lệnh nhập (2 chiều) Đồng bộ trạng thái lệnh nhập (2 chiều) Đồng bộ thông tin KCS (2 chiều) | D11: High | E11: quantm18 | F11: dongnt30 | G11: 5 | H11: 46239 | I11: 46241 | J11: 24h | K11: 24h | L11: 5150
A12: Sub-task | B12: Nhập kho - Tích hợp hệ thống ngoài | BA - Ký số - Thông nhất luồng tích hợp VO | C12: Làm rõ thông tin tích hợp ký số VOFFICE Làm rõ thông tin kết quả ký số có cần gửi file đã kỹ SAP | D12: High | E12: hadd | F12: dongnt30 | G12: 2 | H12: 46239 | I12: 46241 | J12: 24h | K12: 24h | L12: 4417
A13: Sub-task | B13: Nhập kho - Tích hợp hệ thống ngoài | BA - Ký số - Thông nhất luồng tích hợp VO | C13: Làm rõ thông tin tích hợp ký số VOFFICE Làm rõ thông tin kết quả ký số có cần gửi file đã kỹ SAP | D13: High | E13: quantm18 | F13: dongnt30 | G13: 2 | H13: 46239 | I13: 46241 | J13: 24h | K13: 24h | L13: 5150
... A326: Sub-task | B326: Xây dựng nghiệp vụ module Dashboard | BA - Bàn giao tài liệu URS Dashboard V1.0 | C326: Thông tin danh sách các dashboard hai bên đã thống nhất. | D326: High | E326: hadd | F326: dongnt30 | G326: 3 | H326: 46247 | I326: 46247 | J326: 8h | K326: 8h | L326: 4411

Sheet HaDD task sprint
A1: Type | B1: Summary | C1: Description | D1: Priority | E1: Assignee | F1: Reporter | G1: Story point | H1: Start Date | I1: End Date | J1: Original Estimate | K1: Remaining Estimate | L1: Budget/ULNL ( MM) | M1: Thiết bị VPS | N1: Epic link
A2: Component | B2: Dashboard | D2: High | E2: dongnt30 | F2: dongnt30 | G2: 13 | H2: 46235 | I2: 46249 | J2: 80h | K2: 80h | L2: 0
A3: Epic | B3: WEB_Xây dựng nghiệp vụ Dashboard tổng quan | F3: dongnt30
A4: Story | B4: BA - Viết tài liệu BRD | F4: dongnt30 | H4: 46244 | I4: 46245
A5: Sub-task | B5: BA - Viết tài liệu BRD 11/22 biểu đồ | H5: 46244 | I5: 46244
A6: Sub-task | B6: BA - Viết tài liệu 22/22 biểu đồ | H6: 46245 | I6: 46245
A7: Sub-task | B7: BA - Confirm nghiệp vụ | F7: dongnt30 | H7: 46246 | I7: 46246
A8: Sub-task | B8: BA - Update tài liệu BRD | H8: 46246 | I8: 46246
A9: Epic | B9: WEB-Xây dựng nghiệp vụ Dashboard NXK | F9: dongnt30
A10: Story | B10: BA - Viết tài liệu BRD | F10: dongnt30 | H10: 46247 | I10: 46188
A11: Sub-task | B11: BA - Viết tài liệu BRD 9/17 biểu đồ | F11: dongnt30 | H11: 46246 | I11: 46185
A12: Sub-task | B12: BA - Viết tài liệu 17/17 biểu đồ
A13: Story | B13: BA - Confirm nghiệp vụ
A14: Sub-task | B14: BA - Cofirm nghiệp vụ lần 1
A15: Sub-task | B15: BA - Update tài liệu BRD
A16: Epic | B16: WEB-Xây dựng nghiệp vụ Dashboard hiệu xuất nhân sự KPI | F16: dongnt30
A17: Story | B17: BA - Viết tài liệu BRD | F17: dongnt30 | H17: 46247 | I17: 46247
A18: Sub-task | B18: BA - Viết tài liệu BRD 9/19 biểu đồ
A19: Sub-task | B19: BA - Viết tài liệu 19/19 biểu đồ
A20: Story | B20: BA - Confirm nghiệp vụ
A21: Sub-task | B21: BA - Cofirm nghiệp vụ lần 1
A22: Sub-task | B22: BA - Update tài liệu BRD | F22: dongnt30 | H22: 46247 | I22: 46247
A23: Epic | B23: WEB - Xây dựng nghiệp vụ Dashboard Quy hoạch kho | F23: dongnt30
A24: Story | B24: BA - Viết tài liệu BRD
A25: Sub-task | B25: BA - Viết tài liệu BRD biểu đồ
A26: Story | B26: BA - Confirm nghiệp vụ
A27: Sub-task | B27: BA - Cofirm nghiệp vụ lần 1 | F27: dongnt30 | H27: 46248 | I27: 46248
A28: Sub-task | B28: BA - Update tài liệu BRD | F28: dongnt30 | H28: 46248 | I28: 46248
A29: Epic | B29: WEB- Xây dựng nghiệp vụ Dashboard nhân viên | F29: dongnt30 | K29: 40h | L29: 0
A30: Story | B30: BA - Viết tài liệu BRD
A31: Sub-task | B31: BA - Viết tài liệu BRD biểu đồ 12/12
A32: Story | B32: BA - Confirm nghiệp vụ
A33: Sub-task | B33: BA - Cofirm nghiệp vụ lần 1
A34: Sub-task | B34: BA - Update tài liệu BRD | F34: dongnt30 | H34: 46251 | I34: 46251
A35: Epic | B35: Mobile - Xây dụng nghiệp vụ Dashboard hiệu xuất công việc | F35: dongnt30
A36: Story | B36: BA - Viết tài liệu BRD
A37: Sub-task | B37: BA - Viết tài liệu BRD biểu đồ 13/26
A38: Sub-task | B38: BA - Viết tài liệu BRD biểu đồ 26/26
A39: Story | B39: BA - Confirm nghiệp vụ
A40: Sub-task | B40: BA - Cofirm nghiệp vụ lần 1
...

Sheet Trang tính18
A1: Type | B1: Summary | C1: Description | D1: Priority | E1: Assignee | F1: Reporter | G1: Story point | H1: Start Date | I1: End Date | J1: Original Estimate | K1: Remaining Estimate | L1: Budget/ULNL ( MM) | M1: Thiết bị VPS | N1: Epic link
A2: Epic | B2: Nhập kho - Luồng nhập mới | C2: Nhập kho - Luồng nhập mới | D2: High | E2: dongnt30 | F2: dongnt30 | G2: 13 | H2: 46235 | I2: 46249 | J2: 80h | K2: 80h | L2: 0
A3: Story | B3: Hoàn thành tài liệu nhập kho. Trong SRS V1.0.0 có mô tả chi tiết API | C3: Hoàn thành tài liệu nhập kho. Trong SRS V1.0.0 có mô tả chi tiết API | D3: High | E3: quantm18 | F3: dongnt30 | G3: 5 | H3: 46235 | I3: 46240 | J3: 32h | K3: 32h | L3: 0
A4: Sub-task | B4: Hoàn thành tài liệu nhập kho. Trong SRS V1.0.0 có mô tả chi tiết API | BA- Update tài liệu và Fix comment lần 1 | C4: Hoàn thành tài liệu nhập kho. Trong SRS V1.0.0 có mô tả chi tiết API | BA- Update tài liệu và Fix comment lần 1 | D4: High | E4: hadd | F4: dongnt30 | G4: 3 | H4: 46235 | I4: 46235 | J4: 8h | K4: 8h | L4: 4417
A5: Sub-task | B5: Hoàn thành tài liệu nhập kho. Trong SRS V1.0.0 có mô tả chi tiết API | BA- Update tài liệu và Fix comment lần 2 | C5: Hoàn thành tài liệu nhập kho. Trong SRS V1.0.0 có mô tả chi tiết API | BA- Update tài liệu và Fix comment lần 2 | D5: High | E5: hadd | F5: dongnt30 | G5: 3 | H5: 46235 | I5: 46235 | J5: 8h | K5: 8h | L5: 4417
A6: Sub-task | B6: Hoàn thành tài liệu nhập kho. Trong SRS V1.0.0 có mô tả chi tiết API | BA - Mô hình hóa yêu cầu nhập kho theo yêu cầu mới | C6: Hoàn thành tài liệu nhập kho. Trong SRS V1.0.0 có mô tả chi tiết API | BA - Mô hình hóa yêu cầu nhập kho theo yêu cầu mới | D6: High | E6: hadd | F6: dongnt30 | G6: 3 | H6: 46235 | I6: 46240 | J6: 32h | K6: 32h | L6: 4417
A7: Sub-task | B7: Hoàn thành tài liệu nhập kho. Trong SRS V1.0.0 có mô tả chi tiết API | BA - Viết đặc tả API (50%) | C7: Hoàn thành tài liệu nhập kho. Trong SRS V1.0.0 có mô tả chi tiết API | BA - Viết đặc tả API (50%) | D7: High | E7: hadd | F7: dongnt30 | G7: 3 | H7: 46237 | I7: 46237 | J7: 8h | K7: 8h | L7: 4417
A8: Story | B8: Nhập kho - Tích hợp hệ thống ngoài | C8: Nhập kho - Tích hợp hệ thống ngoài | D8: High | E8: dongnt30 | F8: dongnt30 | G8: 13 | H8: 46239 | I8: 46241 | J8: 24h | K8: 24h | L8: 0
A9: Sub-task | B9: Nhập kho - Tích hợp hệ thống ngoài | BA- Thống nhất với nghiệp vụ Maping về số lượng Movement type và lệnh nhập kho | C9: Nhập kho - Tích hợp hệ thống ngoài | BA- Thống nhất với nghiệp vụ Maping về số lượng Movement type và lệnh nhập kho | D9: High | E9: hadd | F9: dongnt30 | G9: 2 | H9: 46239 | I9: 46241 | J9: 24h | K9: 24h | L9: 4417
A10: Sub-task | B10: Nhập kho - Tích hợp hệ thống ngoài | BA- Thống nhất về thông tin đồng bộ SAP | C10: Đồng bộ thông tin lệnh nhập (2 chiều) Đồng bộ trạng thái lệnh nhập (2 chiều) Đồng bộ thông tin KCS (2 chiều) | D10: High | E10: hadd | F10: dongnt30 | G10: 5 | H10: 46239 | I10: 46241 | J10: 24h | K10: 24h | L10: 4417
A11: Sub-task | B11: Nhập kho - Tích hợp hệ thống ngoài | BA- Thống nhất về thông tin đồng bộ SAP | C11: Đồng bộ thông tin lệnh nhập (2 chiều) Đồng bộ trạng thái lệnh nhập (2 chiều) Đồng bộ thông tin KCS (2 chiều) | D11: High | E11: quantm18 | F11: dongnt30 | G11: 5 | H11: 46239 | I11: 46241 | J11: 24h | K11: 24h | L11: 5150
A12: Sub-task | B12: Nhập kho - Tích hợp hệ thống ngoài | BA - Ký số - Thông nhất luồng tích hợp VO | C12: Làm rõ thông tin tích hợp ký số VOFFICE Làm rõ thông tin kết quả ký số có cần gửi file đã kỹ SAP | D12: High | E12: hadd | F12: dongnt30 | G12: 2 | H12: 46239 | I12: 46241 | J12: 24h | K12: 24h | L12: 4417
A13: Sub-task | B13: Nhập kho - Tích hợp hệ thống ngoài | BA - Ký số - Thông nhất luồng tích hợp VO | C13: Làm rõ thông tin tích hợp ký số VOFFICE Làm rõ thông tin kết quả ký số có cần gửi file đã kỹ SAP | D13: High | E13: quantm18 | F13: dongnt30 | G13: 2 | H13: 46239 | I13: 46241 | J13: 24h | K13: 24h | L13: 5150
... A326: Sub-task | B326: Xây dựng nghiệp vụ module Dashboard | BA - Bàn giao tài liệu URS Dashboard V1.0 | C326: Thông tin danh sách các dashboard hai bên đã thống nhất. | D326: High | E326: hadd | F326: dongnt30 | G326: 3 | H326: 46247 | I326: 46247 | J326: 8h | K326: 8h | L326: 4411

Sheet Warehouse resource
A1: STT | B1: Mã NV | C1: Tên nhân viên trên Jira | D1: Account | E1: Email | F1: Nỗ lực thực hiện tháng BU gửi
A2: 1 | B2: 431709 | C2: Nguyễn Văn Trường | D2: =LEFT(E2, FIND("@", E2) - 1) -> truongnv51 | E2: truongnv51@viettel.com.vn | F2: 2030
A3: 2 | B3: 461363 | C3: Lê Hoàng Đức | D3: =IFERROR(LEFT(E3, FIND("@", E3) - 1), "") -> duclh14 | E3: duclh14@viettel.com.vn | F3: 1054
A4: 3 | B4: 465483 | C4: Ngô Doãn Hồng Hiệp | D4: =IFERROR(LEFT(E4, FIND("@", E4) - 1), "") -> hiepndh | E4: hiepndh@viettel.com.vn | F4: 1240
A5: 4 | B5: 475827 | C5: Nguyễn Thành Chiến | D5: =IFERROR(LEFT(E5, FIND("@", E5) - 1), "") -> chiennt11 | E5: chiennt11@viettel.com.vn | F5: 1000
A6: 5 | B6: 476361 | C6: Nguyễn Tấn Đông | D6: =IFERROR(LEFT(E6, FIND("@", E6) - 1), "") -> dongnt30 | E6: dongnt30@viettel.com.vn | F6: 0
A7: 6 | B7: 481564 | C7: Nguyễn Trung Quang | D7: =IFERROR(LEFT(E7, FIND("@", E7) - 1), "") -> quangnt23 | E7: quangnt23@viettel.com.vn | F7: 1590
A8: 7 | B8: 481750 | C8: Nguyễn Duy | D8: =IFERROR(LEFT(E8, FIND("@", E8) - 1), "") -> duyn127 | E8: duyn127@viettel.com.vn | F8: 1240
A9: 8 | B9: 483818 | C9: Trần Minh Quân | D9: =IFERROR(LEFT(E9, FIND("@", E9) - 1), "") -> quantm18 | E9: quantm18@viettel.com.vn | F9: 1030
A10: 9 | B10: 484874 | C10: Bùi Văn Đoàn | D10: =IFERROR(LEFT(E10, FIND("@", E10) - 1), "") -> doanbv2 | E10: doanbv2@viettel.com.vn | F10: 1240
A11: 10 | B11: 485462 | C11: Hoàng Tuấn Anh | D11: =IFERROR(LEFT(E11, FIND("@", E11) - 1), "") -> anhht124 | E11: anhht124@viettel.com.vn | F11: 1240
A12: 11 | B12: 485672 | C12: Nguyễn Huy Tùng | D12: =IFERROR(LEFT(E12, FIND("@", E12) - 1), "") -> tungnh26 | E12: tungnh26@viettel.com.vn | F12: 1590
A13: 12 | B13: 485668 | C13: Ninh Văn Hòa | D13: =IFERROR(LEFT(E13, FIND("@", E13) - 1), "") -> hoanv68 | E13: hoanv68@viettel.com.vn | F13: 1590
A14: 13 | B14: 486016 | C14: Lê Minh Quang | D14: =IFERROR(LEFT(E14, FIND("@", E14) - 1), "") -> quanglm10 | E14: quanglm10@viettel.com.vn | F14: 620
... A16: 15 | B16: 486588 | C16: Đào Đình Hà | D16: =IFERROR(LEFT(E16, FIND("@", E16) - 1), "") -> hadd | E16: hadd@viettel.com.vn | F16: 1590
B17: 487808 | C17: Nguyễn Phan Dương | D17: =IFERROR(LEFT(E17, FIND("@", E17) - 1), "") -> duongnp | E17: duongnp@viettel.com.vn | F17: 1178

Sheet Assign
A1: Summary | B1: Assignee
A2: Hoàn thành tài liệu nhập kho. Trong SRS V1.0.0 có mô tả chi tiết API | B2: quantm18 | C2: hadd
A3: Hoàn thành prototype nhâp kho V1.0.0 | B3: quantm18 | C3: hadd
A4: Mapping API với prototype và nghiệp vụ | B4: chiennt11
A5: Danh sách lệnh nhập | B5: truongnv51 | C5: chiennt11 | D5: duclh14
A6: Xem chi tiết lệnh nhập - Tab Thông tin hàng hóa | B6: anhht124 | C6: hoanv68 | D6: duclh14
A7: Xem chi tiết lệnh nhập - Tab Chứng từ | B7: anhht124 | C7: hoanv68 | D7: duclh14
A8: Xem chi tiết lệnh nhập - Tab Task | B8: anhht124 | C8: hoanv68 | D8: duclh14
A9: Xem chi tiết lệnh nhập - Tab Kết quả KCS | B9: anhht124 | C9: hoanv68 | D9: duclh14
A10: Xem chi tiết lệnh nhập - Tab Vận chuyển | B10: anhht124 | C10: hoanv68 | D10: duclh14
A11: Xem chi tiết lệnh nhập - Tab Lịch sử | B11: anhht124 | C11: hoanv68 | D11: duclh14
A12: [Order] Export Excel | B12: truongnv51 | C12: chiennt11 | D12: duclh14
A13: [Order] Tìm kiếm nhanh | B13: truongnv51 | C13: chiennt11 | D13: duclh14
A14: [Order] Tìm kiếm nâng cao | B14: truongnv51 | C14: chiennt11 | D14: duclh14
A15: Danh sách Task | B15: hiepndh | C15: doanbv2 | D15: duongnp
A16: [Task] Export Excel | B16: hiepndh | C16: doanbv2 | D16: duongnp
... A19: Xác nhận lệnh nhập | B19: hiepndh | C19: hoanv68 | D19: duongnp
A21: Kiểm hàng & Ký BBBG | B21: truongnv51 | C21: nhuandt | D21: hoanv68 | E21: duongnp
A22: Dỡ hàng | B22: doanbv2 | C22: nhuandt | D22: tungnh26
A23: Đưa vào khu chờ nhập | B23: hoanv68 | C23: nhuandt | D23: tungnh26
A24: Thực nhập kho | B24: anhht124 | C24: hoanv68 | D24: tungnh26
A25: Trình ký VOffice | B25: hiepndh | C25: truongnv51 | D25: duongnp
A26: Đưa hàng ra khu đóng gói | B26: hoanv68 | C26: nhuandt | D26: tungnh26
A27: Đóng gói hàng & In tem | B27: doanbv2 | C27: anhht124 | D27: quangnt23
A28: Đưa vào lưu trữ / Putaway | B28: doanbv2 | C28: anhht124 | D28: quangnt23

Sheet Tổng hợp NLTH 1.2024
O1: 21 công chuẩn
A2: STT | B2: Mã NV | C2: Tên nhân viên trên Jira | D2: Email | E2: Phòng/ban | F2: Role | G2: Level | H2: Mã chức danh | I2: Tiêu chuẩn (MM) | J2: Tháng | K2: Năm | L2: Ngày bắt đầu | M2: Ngày kết thúc | N2: Ngày công dự án | O2: Tỉ lệ công theo quá rình | P2: Nỗ lực tiêu chuẩn tháng | Q2: Nỗ lực thực hiện tháng BU gửi | R2: Nỗ lực ngoài sản xuất | S2: Dự án ODC | T2: Mã dự án | U2: Nỗ lực thực hiện chốt tính lương từng quá trình | V2: Nỗ lực tiêu chuẩn tổng các quá trình | W2: Nỗ lực thực hiện chốt tính lương tổng các quá trình | X2: Hệ số K | Y2: Ghi chú | Z2: lặp lại
A3: 1 | B3: 441534 | C3: Bùi Bá Trường | D3: truongbb@viettel,com,vn | E3: BU01 - Quản trị doanh nghiệp | F3: DEV | G3: S | H3: DEV06 | I3: #REF! | J3: 12 | K3: 2023 | L3: 45261 | M3: 45291 | N3: =NETWORKDAYS(L3,M3) -> 21 | O3: =N3/21 -> 1 | P3: =ROUND(IF(S3="ODC",1*O3,I3*O3),3) -> 1 | Q3: 1 | S3: ODC | T3: BU01,MBAL | U3: =IF(AND(Q3>=1,S3="ODC"),P3,Q3) -> 1 | V3: =ROUND(SUMIF($B:$B,B3,P:P),3) -> 1 | W3: =ROUND(SUMIF($B:$B,B3,U:U),3) -> 1 | X3: =ROUND(W3/V3,2) -> 1 | Z3: =COUNTIF($B:$B,B3) -> 1
A4: 2 | B4: 458877 | C4: Bùi Đức Duy | D4: duybd1@viettel,com,vn | E4: BU01 - Quản trị doanh nghiệp | F4: Dev | G4: S | H4: Dev06 | I4: #REF! | J4: 12 | K4: 2023 | L4: 45261 | M4: 45291 | N4: =NETWORKDAYS(L4,M4) -> 21 | O4: =N4/21 -> 1 | P4: =ROUND(IF(S4="ODC",1*O4,I4*O4),3) -> #VALUE! | Q4: 2.27 | S4: NOT ODC | T4: BU01,BCN,NONSAP,Phase2 | U4: =IF(AND(Q4>=1,S4="ODC"),P4,Q4) -> 2.27 | V4: =ROUND(SUMIF($B:$B,B4,P:P),3) -> #VALUE! | W4: =ROUND(SUMIF($B:$B,B4,U:U),3) -> 2.27 | X4: =ROUND(W4/V4,2) -> #VALUE! | Z4: =COUNTIF($B:$B,B4) -> 1
A5: 3 | B5: 434138 | C5: Bùi Minh Tuấn | D5: tuanbm10@viettel,com,vn | E5: BU01 - Quản trị doanh nghiệp | F5: DEV | G5: J+ | H5: DEV03 | I5: #REF! | J5: 12 | K5: 2023 | L5: 45261 | M5: 45291 | N5: =NETWORKDAYS(L5,M5) -> 21 | O5: =N5/21 -> 1 | P5: 1.24 | Q5: 1.24 | S5: NOT ODC | T5: BU01,BCN,NONSAP,Phase2 | U5: =IF(AND(Q5>=1,S5="ODC"),P5,Q5) -> 1.24 | V5: =ROUND(SUMIF($B:$B,B5,P:P),3) -> 1.24 | W5: =ROUND(SUMIF($B:$B,B5,U:U),3) -> 1.24 | X5: =ROUND(W5/V5,2) -> 1 | Z5: =COUNTIF($B:$B,B5) -> 1
A6: 4 | B6: 439038 | C6: Đặng Hữu Hoàn | D6: hoandh@viettel,com,vn | E6: BU01 - Quản trị doanh nghiệp | F6: DEV | G6: J+ | H6: DEV03 | I6: #REF! | J6: 12 | K6: 2023 | L6: 45261 | M6: 45291 | N6: =NETWORKDAYS(L6,M6) -> 21 | O6: =N6/21 -> 1 | P6: =ROUND(IF(S6="ODC",1*O6,I6*O6),3) -> 1 | Q6: 1 | S6: ODC | T6: BU01,BCN,TDTC2,0 | U6: =IF(AND(Q6>=1,S6="ODC"),P6,Q6) -> 1 | V6: =ROUND(SUMIF($B:$B,B6,P:P),3) -> 1 | W6: =ROUND(SUMIF($B:$B,B6,U:U),3) -> 1 | X6: =ROUND(W6/V6,2) -> 1 | Z6: =COUNTIF($B:$B,B6) -> 1
A7: 5 | B7: 436731 | C7: Đặng Như Thanh | D7: thanhdn14@viettel,com,vn | E7: BU01 - Quản trị doanh nghiệp | F7: DEV | G7: M | H7: DEV04 | I7: #REF! | J7: 12 | K7: 2023 | L7: 45261 | M7: 45291 | N7: =NETWORKDAYS(L7,M7) -> 21 | O7: =N7/21 -> 1 | P7: =ROUND(IF(S7="ODC",1*O7,I7*O7),3) -> 1 | Q7: 1 | S7: ODC | T7: BU01,MBAL | U7: =IF(AND(Q7>=1,S7="ODC"),P7,Q7) -> 1 | V7: =ROUND(SUMIF($B:$B,B7,P:P),3) -> 1 | W7: =ROUND(SUMIF($B:$B,B7,U:U),3) -> 1 | X7: =ROUND(W7/V7,2) -> 1 | Z7: =COUNTIF($B:$B,B7) -> 1
A8: 6 | B8: 291197 | C8: Đinh Thị Hường | D8: huongdt157@viettel,com,vn | E8: BU01 - Quản trị doanh nghiệp | F8: TESTER | G8: M | H8: TESTER04 | I8: #REF! | J8: 12 | K8: 2023 | L8: 45261 | M8: 45291 | N8: =NETWORKDAYS(L8,M8) -> 21 | O8: =N8/21 -> 1 | P8: =ROUND(IF(S8="ODC",1*O8,I8*O8),3) -> 1 | Q8: 1 | S8: ODC | T8: BU01,MBAL | U8: =IF(AND(Q8>=1,S8="ODC"),P8,Q8) -> 1 | V8: =ROUND(SUMIF($B:$B,B8,P:P),3) -> 1 | W8: =ROUND(SUMIF($B:$B,B8,U:U),3) -> 1 | X8: =ROUND(W8/V8,2) -> 1 | Z8: =COUNTIF($B:$B,B8) -> 1
A9: 7 | B9: 428532 | C9: Đinh Thị Thảo | D9: thaodt48@viettel,com,vn | E9: BU01 - Quản trị doanh nghiệp | F9: TESTER | G9: J | H9: TESTER02 | I9: #REF! | J9: 12 | K9: 2023 | L9: 45261 | M9: 45291 | N9: =NETWORKDAYS(L9,M9) -> 21 | O9: =N9/21 -> 1 | P9: =ROUND(IF(S9="ODC",1*O9,I9*O9),3) -> 1 | Q9: 0.88 | S9: ODC | T9: BU01,MBAL | U9: =IF(AND(Q9>=1,S9="ODC"),P9,Q9) -> 0.88 | V9: =ROUND(SUMIF($B:$B,B9,P:P),3) -> 1 | W9: =ROUND(SUMIF($B:$B,B9,U:U),3) -> 0.88 | X9: =ROUND(W9/V9,2) -> 0.88 | Z9: =COUNTIF($B:$B,B9) -> 1
A10: 8 | B10: 427333 | C10: Đỗ Đức Bình | D10: binhdd3@viettel,com,vn | E10: BU01 - Quản trị doanh nghiệp | F10: DEV | G10: M | H10: DEV04 | I10: #REF! | J10: 12 | K10: 2023 | L10: 45261 | M10: 45291 | N10: =NETWORKDAYS(L10,M10) -> 21 | O10: =N10/21 -> 1 | P10: =ROUND(IF(S10="ODC",1*O10,I10*O10),3) -> 1 | Q10: 1 | S10: ODC | T10: BU01,MBAL | U10: =IF(AND(Q10>=1,S10="ODC"),P10,Q10) -> 1 | V10: =ROUND(SUMIF($B:$B,B10,P:P),3) -> 1 | W10: =ROUND(SUMIF($B:$B,B10,U:U),3) -> 1 | X10: =ROUND(W10/V10,2) -> 1 | Z10: =COUNTIF($B:$B,B10) -> 1
A11: 9 | B11: 292508 | C11: Hoàng Thị Huyền | D11: huyenht25@viettel,com,vn | E11: BU01 - Quản trị doanh nghiệp | F11: BA | G11: J+ | H11: BA03 | I11: #REF! | J11: 12 | K11: 2023 | L11: 45261 | M11: 45291 | N11: =NETWORKDAYS(L11,M11) -> 21 | O11: =N11/21 -> 1 | P11: =ROUND(IF(S11="ODC",1*O11,I11*O11),3) -> 1 | Q11: 1 | S11: ODC | T11: BU01,MBAL | U11: =IF(AND(Q11>=1,S11="ODC"),P11,Q11) -> 1 | V11: =ROUND(SUMIF($B:$B,B11,P:P),3) -> 1 | W11: =ROUND(SUMIF($B:$B,B11,U:U),3) -> 1 | X11: =ROUND(W11/V11,2) -> 1 | Z11: =COUNTIF($B:$B,B11) -> 1
A12: 10 | B12: 455599 | C12: Lê Hồng Thanh | D12: THANHLH16@VIETTEL,COM,VN | E12: BU01 - Quản trị doanh nghiệp | F12: DEV | G12: M+ | H12: DEV05 | I12: #REF! | J12: 12 | K12: 2023 | L12: 45261 | M12: 45291 | N12: =NETWORKDAYS(L12,M12) -> 21 | O12: =N12/21 -> 1 | P12: =ROUND(IF(S12="ODC",1*O12,I12*O12),3) -> 1 | Q12: 1 | S12: ODC | T12: BU01,MBAL | U12: =IF(AND(Q12>=1,S12="ODC"),P12,Q12) -> 1 | V12: =ROUND(SUMIF($B:$B,B12,P:P),3) -> 1 | W12: =ROUND(SUMIF($B:$B,B12,U:U),3) -> 1 | X12: =ROUND(W12/V12,2) -> 1 | Z12: =COUNTIF($B:$B,B12) -> 1
A13: 11 | B13: 456641 | C13: Nguyễn Anh Tuấn | D13: TUANNA794@VIETTEL,COM,VN | E13: BU01 - Quản trị doanh nghiệp | F13: DEV | G13: M | H13: DEV04 | I13: #REF! | J13: 12 | K13: 2023 | L13: 45261 | M13: 45291 | N13: =NETWORKDAYS(L13,M13) -> 21 | O13: =N13/21 -> 1 | P13: =ROUND(IF(S13="ODC",1*O13,I13*O13),3) -> 1 | Q13: 1 | S13: ODC | T13: BU01,MBAL | U13: =IF(AND(Q13>=1,S13="ODC"),P13,Q13) -> 1 | V13: =ROUND(SUMIF($B:$B,B13,P:P),3) -> 1 | W13: =ROUND(SUMIF($B:$B,B13,U:U),3) -> 1 | X13: =ROUND(W13/V13,2) -> 1 | Z13: =COUNTIF($B:$B,B13) -> 1
A14: 12 | B14: 272968 | C14: Nguyễn Đức Mạnh | D14: manhnd33@viettel,com,vn | E14: BU01 - Quản trị doanh nghiệp | F14: DEV | G14: S | H14: DEV06 | I14: #REF! | J14: 12 | K14: 2023 | L14: 45261 | M14: 45291 | N14: =NETWORKDAYS(L14,M14) -> 21 | O14: =N14/21 -> 1 | P14: =ROUND(IF(S14="ODC",1*O14,I14*O14),3) -> 1 | Q14: 1 | S14: ODC | T14: BU01,MBAL | U14: =IF(AND(Q14>=1,S14="ODC"),P14,Q14) -> 1 | V14: =ROUND(SUMIF($B:$B,B14,P:P),3) -> 1 | W14: =ROUND(SUMIF($B:$B,B14,U:U),3) -> 1 | X14: =ROUND(W14/V14,2) -> 1 | Z14: =COUNTIF($B:$B,B14) -> 1
A15: 13 | B15: 281845 | C15: Nguyễn Hoàng Giang | D15: giangnh34@viettel,com,vn | E15: BU01 - Quản trị doanh nghiệp | F15: DEV | G15: M | H15: DEV04 | I15: #REF! | J15: 12 | K15: 2023 | L15: 45261 | M15: 45291 | N15: =NETWORKDAYS(L15,M15) -> 21 | O15: =N15/21 -> 1 | P15: =ROUND(IF(S15="ODC",1*O15,I15*O15),3) -> 1 | Q15: 1 | S15: ODC | T15: BU01,MBAL | U15: =IF(AND(Q15>=1,S15="ODC"),P15,Q15) -> 1 | V15: =ROUND(SUMIF($B:$B,B15,P:P),3) -> 1 | W15: =ROUND(SUMIF($B:$B,B15,U:U),3) -> 1 | X15: =ROUND(W15/V15,2) -> 1 | Z15: =COUNTIF($B:$B,B15) -> 1
A16: 14 | B16: 434038 | C16: Nguyễn Thị Hòa | D16: hoant224@viettel,com,vn | E16: BU01 - Quản trị doanh nghiệp | F16: TESTER | G16: M+ | H16: TESTER05 | I16: #REF! | J16: 12 | K16: 2023 | L16: 45261 | M16: 45291 | N16: =NETWORKDAYS(L16,M16) -> 21 | O16: =N16/21 -> 1 | P16: =ROUND(IF(S16="ODC",1*O16,I16*O16),3) -> 1 | Q16: 1 | S16: ODC | T16: BU01,MBAL | U16: =IF(AND(Q16>=1,S16="ODC"),P16,Q16) -> 1 | V16: =ROUND(SUMIF($B:$B,B16,P:P),3) -> 1 | W16: =ROUND(SUMIF($B:$B,B16,U:U),3) -> 1 | X16: =ROUND(W16/V16,2) -> 1 | Z16: =COUNTIF($B:$B,B16) -> 1
A17: 15 | B17: 447599 | C17: Nguyễn Thị Quỳnh Mai | D17: MAINTQ2@VIETTEL,COM,VN | E17: BU01 - Quản trị doanh nghiệp | F17: BA | G17: J+ | H17: BA03 | I17: #REF! | J17: 12 | K17: 2023 | L17: 45261 | M17: 45291 | N17: =NETWORKDAYS(L17,M17) -> 21 | O17: =N17/21 -> 1 | P17: =ROUND(IF(S17="ODC",1*O17,I17*O17),3) -> 1 | Q17: 1 | S17: ODC | T17: BU01,BCN,TDTC2,0 | U17: =IF(AND(Q17>=1,S17="ODC"),P17,Q17) -> 1 | V17: =ROUND(SUMIF($B:$B,B17,P:P),3) -> 1 | W17: =ROUND(SUMIF($B:$B,B17,U:U),3) -> 1 | X17: =ROUND(W17/V17,2) -> 1 | Z17: =COUNTIF($B:$B,B17) -> 1
A18: 16 | B18: 435013 | C18: Nguyễn Xuân Quy | D18: quynx6@viettel,com,vn | E18: BU01 - Quản trị doanh nghiệp | F18: DEV | G18: S | H18: DEV06 | I18: #REF! | J18: 12 | K18: 2023 | L18: 45261 | M18: 45291 | N18: 11 | O18: =N18/21 -> 0.52380952 | P18: =ROUND(IF(S18="ODC",1*O18,I18*O18),3) -> 0.524 | Q18: 0.52 | S18: ODC | T18: BU01,MBAL | U18: =IF(AND(Q18>=1,S18="ODC"),P18,Q18) -> 0.52 | V18: =ROUND(SUMIF($B:$B,B18,P:P),3) -> 0.524 | W18: =ROUND(SUMIF($B:$B,B18,U:U),3) -> 0.52 | X18: =ROUND(W18/V18,2) -> 0.99 | Z18: =COUNTIF($B:$B,B18) -> 1
A19: 17 | B19: 293052 | C19: Phạm Thị Sâm | D19: sampt1@viettel,com,vn | E19: BU01 - Quản trị doanh nghiệp | F19: TESTER | G19: J+ | H19: TESTER03 | I19: #REF! | J19: 12 | K19: 2023 | L19: 45261 | M19: 45291 | N19: 20 | O19: =N19/21 -> 0.95238095 | P19: =ROUND(IF(S19="ODC",1*O19,I19*O19),3) -> 0.952 | Q19: 0.95 | S19: ODC | T19: BU01,MBAL | U19: =IF(AND(Q19>=1,S19="ODC"),P19,Q19) -> 0.95 | V19: =ROUND(SUMIF($B:$B,B19,P:P),3) -> 0.952 | W19: =ROUND(SUMIF($B:$B,B19,U:U),3) -> 0.95 | X19: =ROUND(W19/V19,2) -> 1 | Z19: =COUNTIF($B:$B,B19) -> 1
A20: 18 | B20: 429575 | C20: Phạm Thị Thu | D20: thupt26@viettel,com,vn | E20: BU01 - Quản trị doanh nghiệp | F20: TESTER | G20: J+ | H20: TESTER03 | I20: #REF! | J20: 12 | K20: 2023 | L20: 45261 | M20: 45291 | N20: =NETWORKDAYS(L20,M20) -> 21 | O20: =N20/21 -> 1 | P20: =ROUND(IF(S20="ODC",1*O20,I20*O20),3) -> #VALUE! | Q20: 1.19 | S20: NOT ODC | T20: BU01,BCN,NONSAP,Phase2 | U20: =IF(AND(Q20>=1,S20="ODC"),P20,Q20) -> 1.19 | V20: =ROUND(SUMIF($B:$B,B20,P:P),3) -> #VALUE! | W20: =ROUND(SUMIF($B:$B,B20,U:U),3) -> 1.19 | X20: =ROUND(W20/V20,2) -> #VALUE! | Z20: =COUNTIF($B:$B,B20) -> 1
A21: 19 | B21: 212015 | C21: Phí Anh Tuân | D21: tuanpa50@viettel,com,vn | E21: BU01 - Quản trị doanh nghiệp | F21: BA | G21: S | H21: BA06 | I21: #REF! | J21: 12 | K21: 2023 | L21: 45261 | M21: 45291 | N21: =NETWORKDAYS(L21,M21) -> 21 | O21: =N21/21 -> 1 | P21: =ROUND(IF(S21="ODC",1*O21,I21*O21),3) -> #VALUE! | Q21: 2.33 | S21: NOT ODC | T21: BU01,NCB,OFFICE | U21: 2.33 | V21: =ROUND(SUMIF($B:$B,B21,P:P),3) -> #VALUE! | W21: =ROUND(SUMIF($B:$B,B21,U:U),3) -> 2.33 | X21: =ROUND(W21/V21,2) -> #VALUE! | Z21: =COUNTIF($B:$B,B21) -> 1
A22: 20 | B22: 277202 | C22: Trương Văn Luân | D22: luantv13@viettel,com,vn | E22: BU01 - Quản trị doanh nghiệp | F22: DEV | G22: M | H22: DEV04 | I22: #REF! | J22: 12 | K22: 2023 | L22: 45261 | M22: 45291 | N22: 20 | O22: =N22/21 -> 0.95238095 | P22: =ROUND(IF(S22="ODC",1*O22,I22*O22),3) -> 0.952 | Q22: 0.95 | S22: ODC | T22: BU01,MBAL | U22: =IF(AND(Q22>=1,S22="ODC"),P22,Q22) -> 0.95 | V22: =ROUND(SUMIF($B:$B,B22,P:P),3) -> 0.952 | W22: =ROUND(SUMIF($B:$B,B22,U:U),3) -> 0.95 | X22: =ROUND(W22/V22,2) -> 1 | Z22: =COUNTIF($B:$B,B22) -> 1
A23: 21 | B23: 430895 | C23: Vũ Văn Phúc | D23: phucvv4@viettel,com,vn | E23: BU01 - Quản trị doanh nghiệp | F23: DEV | G23: M+ | H23: DEV05 | I23: #REF! | J23: 12 | K23: 2023 | L23: 45261 | M23: 45291 | N23: =NETWORKDAYS(L23,M23) -> 21 | O23: =N23/21 -> 1 | P23: =ROUND(IF(S23="ODC",1*O23,I23*O23),3) -> 1 | Q23: 1 | S23: ODC | T23: BU01,MBAL | U23: =IF(AND(Q23>=1,S23="ODC"),P23,Q23) -> 1 | V23: =ROUND(SUMIF($B:$B,B23,P:P),3) -> 1 | W23: =ROUND(SUMIF($B:$B,B23,U:U),3) -> 1 | X23: =ROUND(W23/V23,2) -> 1 | Z23: =COUNTIF($B:$B,B23) -> 1
A24: 22 | B24: 439024 | C24: Đào Diễm Hương | D24: huongdd8@viettel,com,vn | E24: BU01 - Quản trị doanh nghiệp | F24: TESTER | G24: M | H24: TESTER04 | I24: #REF! | J24: 12 | K24: 2023 | L24: 45261 | M24: 45291 | N24: =NETWORKDAYS(L24,M24) -> 21 | O24: =N24/21 -> 1 | P24: =ROUND(IF(S24="ODC",1*O24,I24*O24),3) -> 1 | Q24: 1 | S24: ODC | T24: BU01,BCN,TDTC2,0 | U24: =IF(AND(Q24>=1,S24="ODC"),P24,Q24) -> 1 | V24: =ROUND(SUMIF($B:$B,B24,P:P),3) -> 1 | W24: =ROUND(SUMIF($B:$B,B24,U:U),3) -> 1 | X24: =ROUND(W24/V24,2) -> 1 | Z24: =COUNTIF($B:$B,B24) -> 1
A25: 23 | B25: 283181 | C25: Lê Thế Long | D25: longlt23@viettel,com,vn | E25: BU01 - Quản trị doanh nghiệp | F25: BA | G25: M | H25: BA04 | I25: #REF! | J25: 12 | K25: 2023 | L25: 45261 | M25: 45285 | N25: =NETWORKDAYS(L25,M25) -> 17 | O25: =N25/21 -> 0.80952381 | P25: =ROUND(IF(S25="ODC",1*O25,I25*O25),3) -> #VALUE! | Q25: 1.287 | S25: NOT ODC | T25: BU01,BCN,NONSAP,Phase2 | U25: =IF(AND(Q25>=1,S25="ODC"),P25,Q25) -> 1.287 | V25: =ROUND(SUMIF($B:$B,B25,P:P),3) -> #VALUE! | W25: =ROUND(SUMIF($B:$B,B25,U:U),3) -> 1.287 | X25: =ROUND(W25/V25,2) -> #VALUE! | Z25: =COUNTIF($B:$B,B25) -> 1
A26: 24 | B26: 284324 | C26: Nguyễn Văn Huy | D26: huynv55@viettel,com,vn | E26: BU01 - Quản trị doanh nghiệp | F26: DEV | G26: J | H26: DEV02 | I26: #REF! | J26: 12 | K26: 2023 | L26: 45292 | M26: 45322 | N26: =NETWORKDAYS(L26,M26) -> 23 | O26: =N26/21 -> 1.0952381 | P26: =ROUND(IF(S26="ODC",1*O26,I26*O26),3) -> #VALUE! | Q26: 0.6 | S26: NOT ODC | T26: BU05,VTT,MyViettel | U26: =IF(AND(Q26>=1,S26="ODC"),P26,Q26) -> 0.6 | V26: =ROUND(SUMIF($B:$B,B26,P:P),3) -> #VALUE! | W26: =ROUND(SUMIF($B:$B,B26,U:U),3) -> 0.6 | X26: =ROUND(W26/V26,2) -> #VALUE! | Z26: =COUNTIF($B:$B,B26) -> 1
A27: 25 | B27: 428983 | C27: Ngô Thế Hưng | D27: hungnt209@viettel,com,vn | E27: BU03 | F27: DEV | G27: M+ | H27: DEV05 | I27: 2.03 | J27: 12 | K27: 2023 | L27: 44938 | M27: 12/31/2023 | N27: 20 | O27: 1 | P27: 1 | Q27: 1 | S27: ODC | T27: BU03,VDS,VTM,FCC | U27: =IF(AND(Q27>=1,S27="ODC"),P27,Q27) -> 1 | V27: =ROUND(SUMIF($B:$B,B27,P:P),3) -> 1 | W27: =ROUND(SUMIF($B:$B,B27,U:U),3) -> 1 | X27: =ROUND(W27/V27,2) -> 1 | Z27: =COUNTIF($B:$B,B27) -> 1
A28: 26 | B28: 428979 | C28: Nguyễn Thị Huyền | D28: huyennt166@viettel,com,vn | E28: BU03 | F28: BA | G28: S | H28: BA06 | I28: 2.33 | J28: 12 | K28: 2023 | L28: 44938 | M28: 12/31/2023 | N28: 20 | O28: 1 | P28: 1 | Q28: 0.95 | S28: ODC | T28: BU03,VDS,VTM,FCC | U28: =IF(AND(Q28>=1,S28="ODC"),P28,Q28) -> 0.95 | V28: =ROUND(SUMIF($B:$B,B28,P:P),3) -> 1 | W28: =ROUND(SUMIF($B:$B,B28,U:U),3) -> 0.95 | X28: =ROUND(W28/V28,2) -> 0.95 | Z28: =COUNTIF($B:$B,B28) -> 1
A29: 27 | B29: 428991 | C29: Nguyễn Đức Quân | D29: quannd16@viettel,com,vn | E29: BU03 | F29: DEV | G29: J | H29: DEV02 | I29: 1 | J29: 12 | K29: 2023 | L29: 44938 | M29: 12/31/2023 | N29: 20 | O29: 1 | P29: 1 | Q29: 0.98 | S29: ODC | T29: BU03,VDS,VTM,FCC | U29: =IF(AND(Q29>=1,S29="ODC"),P29,Q29) -> 0.98 | V29: =ROUND(SUMIF($B:$B,B29,P:P),3) -> 1 | W29: =ROUND(SUMIF($B:$B,B29,U:U),3) -> 0.98 | X29: =ROUND(W29/V29,2) -> 0.98 | Z29: =COUNTIF($B:$B,B29) -> 1
A30: 28 | B30: 434053 | C30: Nguyễn Hoài Sơn | D30: sonnh70@viettel,com,vn | E30: BU03 | F30: DEV | G30: J | H30: DEV02 | I30: 1 | J30: 12 | K30: 2023 | L30: 44938 | M30: 12/31/2023 | N30: 20 | O30: 1 | P30: 1 | Q30: 0.93 | S30: ODC | T30: BU03,VDS,VTM,FCC | U30: =IF(AND(Q30>=1,S30="ODC"),P30,Q30) -> 0.93 | V30: =ROUND(SUMIF($B:$B,B30,P:P),3) -> 1 | W30: =ROUND(SUMIF($B:$B,B30,U:U),3) -> 0.93 | X30: =ROUND(W30/V30,2) -> 0.93 | Z30: =COUNTIF($B:$B,B30) -> 1
A31: 29 | B31: 432653 | C31: Trần Thị Thanh Thanh | D31: thanhttt13@viettel,com,vn | E31: BU03 | F31: DEV | G31: J+ | H31: DEV03 | I31: 1.24 | J31: 12 | K31: 2023 | L31: 44938 | M31: 12/31/2023 | N31: 20 | O31: 1 | P31: 1 | Q31: 1 | S31: ODC | T31: BU03,VDS,VTM,FCC | U31: =IF(AND(Q31>=1,S31="ODC"),P31,Q31) -> 1 | V31: =ROUND(SUMIF($B:$B,B31,P:P),3) -> 1 | W31: =ROUND(SUMIF($B:$B,B31,U:U),3) -> 1 | X31: =ROUND(W31/V31,2) -> 1 | Z31: =COUNTIF($B:$B,B31) -> 1
A32: 30 | B32: 428711 | C32: Vũ Thị Nga | D32: ngavt16@viettel,com,vn | E32: BU03 | F32: Tester | G32: M | H32: Tester04 | I32: 1.41 | J32: 12 | K32: 2023 | L32: 44938 | M32: 12/31/2023 | N32: 20 | O32: 1 | P32: 1 | Q32: 1 | S32: ODC | T32: BU03,VDS,VTM,FCC | U32: =IF(AND(Q32>=1,S32="ODC"),P32,Q32) -> 1 | V32: =ROUND(SUMIF($B:$B,B32,P:P),3) -> 1 | W32: =ROUND(SUMIF($B:$B,B32,U:U),3) -> 1 | X32: =ROUND(W32/V32,2) -> 1 | Z32: =COUNTIF($B:$B,B32) -> 1
A33: 31 | B33: 439022 | C33: Nguyễn Thị Ngọc Yến | D33: yenntn17@viettel,com,vn | E33: BU03 | F33: Tester | G33: J | H33: Tester02 | I33: 0.86 | J33: 12 | K33: 2023 | L33: 44938 | M33: 12/31/2023 | N33: 20 | O33: 1 | P33: 1 | Q33: 0.95 | S33: ODC | T33: BU03,VDS,VTM,FCC | U33: =IF(AND(Q33>=1,S33="ODC"),P33,Q33) -> 0.95 | V33: =ROUND(SUMIF($B:$B,B33,P:P),3) -> 1 | W33: =ROUND(SUMIF($B:$B,B33,U:U),3) -> 0.95 | X33: =ROUND(W33/V33,2) -> 0.95 | Z33: =COUNTIF($B:$B,B33) -> 1
A34: 32 | B34: 431986 | C34: Phạm Hồng Quân | D34: quanph25@viettel,com,vn | E34: BU03 | F34: DEV | G34: M | H34: DEV04 | I34: 1.59 | J34: 12 | K34: 2023 | L34: 44938 | M34: 12/31/2023 | N34: 20 | O34: 1 | P34: 1 | Q34: 0.95 | S34: ODC | T34: BU03,VDS,VTM,FCC | U34: =IF(AND(Q34>=1,S34="ODC"),P34,Q34) -> 0.95 | V34: =ROUND(SUMIF($B:$B,B34,P:P),3) -> 1 | W34: =ROUND(SUMIF($B:$B,B34,U:U),3) -> 0.95 | X34: =ROUND(W34/V34,2) -> 0.95 | Z34: =COUNTIF($B:$B,B34) -> 1
A35: 33 | B35: 450265 | C35: Nguyễn Ngọc Huy | D35: huynn26@viettel,com,vn | E35: BU03 | F35: DEV | G35: J | H35: DEV02 | I35: 1 | J35: 12 | K35: 2023 | L35: 44938 | M35: 12/31/2023 | N35: 20 | O35: 1 | P35: 1 | Q35: 1 | S35: ODC | T35: BU03,VDS,VTM,FCC | U35: =IF(AND(Q35>=1,S35="ODC"),P35,Q35) -> 1 | V35: =ROUND(SUMIF($B:$B,B35,P:P),3) -> 1 | W35: =ROUND(SUMIF($B:$B,B35,U:U),3) -> 1 | X35: =ROUND(W35/V35,2) -> 1 | Z35: =COUNTIF($B:$B,B35) -> 1
A36: 34 | B36: 452011 | C36: Phạm Ngọc Minh | D36: minhpn13@viettel,com,vn | E36: BU03 | F36: DEV | G36: J+ | H36: DEV03 | I36: 1.24 | J36: 12 | K36: 2023 | L36: 44938 | M36: 12/31/2023 | N36: 20 | O36: 1 | P36: 1 | Q36: 0.95 | S36: ODC | T36: BU03,VDS,VTM,FCC | U36: =IF(AND(Q36>=1,S36="ODC"),P36,Q36) -> 0.95 | V36: =ROUND(SUMIF($B:$B,B36,P:P),3) -> 1 | W36: =ROUND(SUMIF($B:$B,B36,U:U),3) -> 0.95 | X36: =ROUND(W36/V36,2) -> 0.95 | Z36: =COUNTIF($B:$B,B36) -> 1
A37: 35 | B37: 453223 | C37: Nguyễn Tuấn Anh | D37: anhnt682@viettel,com,vn | E37: BU03 | F37: DEV | G37: J | H37: DEV02 | I37: 1 | J37: 12 | K37: 2023 | L37: 44938 | M37: 12/31/2023 | N37: 20 | O37: 1 | P37: 1 | Q37: 1 | S37: ODC | T37: BU03,VDS,VTM,FCC | U37: =IF(AND(Q37>=1,S37="ODC"),P37,Q37) -> 1 | V37: =ROUND(SUMIF($B:$B,B37,P:P),3) -> 1 | W37: =ROUND(SUMIF($B:$B,B37,U:U),3) -> 1 | X37: =ROUND(W37/V37,2) -> 1 | Z37: =COUNTIF($B:$B,B37) -> 1
A38: 36 | B38: 456631 | C38: Lại Tuấn Khương | D38: khuonglt@viettel,com,vn | E38: BU03 | F38: DEV | G38: J | H38: DEV02 | I38: 1 | J38: 12 | K38: 2023 | L38: 44938 | M38: 12/31/2023 | N38: 20 | O38: 1 | P38: 1 | Q38: 1 | S38: ODC | T38: BU03,VDS,VTM,FCC | U38: =IF(AND(Q38>=1,S38="ODC"),P38,Q38) -> 1 | V38: =ROUND(SUMIF($B:$B,B38,P:P),3) -> 1 | W38: =ROUND(SUMIF($B:$B,B38,U:U),3) -> 1 | X38: =ROUND(W38/V38,2) -> 1 | Z38: =COUNTIF($B:$B,B38) -> 1
... A50: 48 | B50: 453003 | C50: Vũ Thái Sơn | D50: sonvt25@viettel,com,vn | E50: BU03 | F50: DEV | G50: S | H50: DEV06 | I50: 2.27 | J50: 12 | K50: 2023 | L50: 44938 | M50: 12/31/2023 | N50: 20 | O50: 1 | P50: 2.27 | Q50: 2.16 | S50: NOT ODC | T50: BU03,VDS,CT,Phase1 | U50: =IF(AND(Q50>=1,S50="ODC"),P50,Q50) -> 2.16 | V50: =ROUND(SUMIF($B:$B,B50,P:P),3) -> 2.27 | W50: =ROUND(SUMIF($B:$B,B50,U:U),3) -> 2.16 | X50: =ROUND(W50/V50,2) -> 0.95 | Z50: =COUNTIF($B:$B,B50) -> 1
A51: 49 | B51: 454351 | C51: Hoàng Thị Thu Hằng | D51: hanghtt18@viettel,com,vn | E51: BU03 | F51: Tester | G51: F | H51: Tester01 | I51: 0.51 | J51: 12 | K51: 2023 | L51: 44938 | M51: 45242 | N51: 7 | O51: 0.35 | P51: 0.179 | Q51: 0.18 | S51: NOT ODC | T51: BU03,VDS,CT,Phase1 | U51: =IF(AND(Q51>=1,S51="ODC"),P51,Q51) -> 0.18 | V51: =ROUND(SUMIF($B:$B,B51,P:P),3) -> 0.511 | W51: =ROUND(SUMIF($B:$B,B51,U:U),3) -> 0.51 | X51: =ROUND(W51/V51,2) -> 1 | Z51: =COUNTIF($B:$B,B51) -> 2
...

Sheet Tổng hợp NLTH 2.2024
B1: CÔNG TY ĐẦU TƯ CÔNG NGHỆ VIETTEL PHÒNG QUẢN LÝ DỰ ÁN Số: …,/TB-PMO | R1: CỘNG HOÀ XÃ HỘI CHỦ NGHĨA VIỆT NAM Độc lập - Tự do - Hạnh phúc
F8: BẢNG TỔNG HỢP NỖ LỰC THÁNG 02,2024
A11: STT | B11: Mã NV | C11: Tên nhân viên trên Jira | D11: Email | E11: Phòng/ban | F11: Role | G11: Level | H11: Mã chức danh | I11: Tiêu chuẩn (MM) | J11: Tháng | K11: Năm | L11: Ngày bắt đầu | M11: Ngày kết thúc | N11: Ngày công dự án | O11: Tỉ lệ công theo quá trình | P11: Nỗ lực tiêu chuẩn tháng | Q11: Nỗ lực thực hiện tháng BU gửi | R11: Nỗ lực ngoài sản xuất | S11: Dự án ODC | T11: Mã dự án | U11: Nỗ lực thực hiện chốt tính lương từng quá trình | V11: Nỗ lực tiêu chuẩn tổng các quá trình | W11: Nỗ lực thực hiện chốt tính lương tổng các quá trình | X11: Hệ số K | Y11: Ghi chú | Z11: lặp lại
A12: 1 | B12: 455381 | C12: Đàm Thị Khánh Huyền | D12: HUYENDTK1@VIETTEL,COM,VN | E12: BU05 - Viễn thông | F12: TESTER | G12: J | H12: TESTER02 | I12: #REF! | J12: 2 | K12: 2024 | L12: 45323 | M12: 45351 | N12: 16 | O12: =N12/16 -> 1 | P12: =ROUND(IF(S12="ODC",1*O12,I12*O12),3) -> 1 | Q12: 0.8125 | S12: ODC | T12: BU05,VTCC,DMP | U12: =IF(AND(Q12>=1,S12="ODC"),P12,Q12) -> 0.8125 | V12: =ROUND(SUMIF($B:$B,B12,P:P),3) -> 1 | W12: =ROUND(SUMIF($B:$B,B12,U:U),3) -> 0.813 | X12: =ROUND(W12/V12,2) -> 0.81 | Z12: =COUNTIF($B:$B,B12) -> 1
A13: =A12+1 -> 2 | B13: 438179 | C13: Phạm Thị Trang | D13: trangpt62@viettel,com,vn | E13: BU05 - Viễn thông | F13: TESTER | G13: F | H13: TESTER02 | I13: #REF! | J13: 2 | K13: 2024 | L13: 45323 | M13: 45351 | N13: 16 | O13: =N13/16 -> 1 | P13: =ROUND(IF(S13="ODC",1*O13,I13*O13),3) -> 1 | Q13: 0.9375 | S13: ODC | T13: BU05,VTCC,DMP | U13: =IF(AND(Q13>=1,S13="ODC"),P13,Q13) -> 0.9375 | V13: =ROUND(SUMIF($B:$B,B13,P:P),3) -> 1 | W13: =ROUND(SUMIF($B:$B,B13,U:U),3) -> 0.938 | X13: =ROUND(W13/V13,2) -> 0.94 | Z13: =COUNTIF($B:$B,B13) -> 1
A14: 3 | B14: 429608 | C14: Đình Văn Quân | D14: quandv17@viettel,com,vn | E14: BU05 - Viễn thông | F14: DEV | G14: J | H14: DEV02 | I14: #REF! | J14: 2 | K14: 2024 | L14: 45323 | M14: 45351 | N14: 16 | O14: =N14/16 -> 1 | P14: =ROUND(IF(S14="ODC",1*O14,I14*O14),3) -> 1 | Q14: 1 | S14: ODC | T14: BU05,VTCC,DMP | U14: =IF(AND(Q14>=1,S14="ODC"),P14,Q14) -> 1 | V14: =ROUND(SUMIF($B:$B,B14,P:P),3) -> 1 | W14: =ROUND(SUMIF($B:$B,B14,U:U),3) -> 1 | X14: =ROUND(W14/V14,2) -> 1 | Z14: =COUNTIF($B:$B,B14) -> 1
A15: 4 | B15: 430741 | C15: Đinh Văn Tuấn | D15: tuandv25@viettel,com,vn | E15: BU05 - Viễn thông | F15: DEV | G15: J+ | H15: DEV03 | I15: #REF! | J15: 2 | K15: 2024 | L15: 45323 | M15: 45351 | N15: 16 | O15: =N15/16 -> 1 | P15: =ROUND(IF(S15="ODC",1*O15,I15*O15),3) -> 1 | Q15: 0.96875 | S15: ODC | T15: BU05,VTCC,DMP | U15: =IF(AND(Q15>=1,S15="ODC"),P15,Q15) -> 0.96875 | V15: =ROUND(SUMIF($B:$B,B15,P:P),3) -> 1 | W15: =ROUND(SUMIF($B:$B,B15,U:U),3) -> 0.969 | X15: =ROUND(W15/V15,2) -> 0.97 | Z15: =COUNTIF($B:$B,B15) -> 1
A16: 5 | B16: 429615 | C16: Đỗ Văn Chiển | D16: chiendv8@viettel,com,vn | E16: BU05 - Viễn thông | F16: DEV | G16: J | H16: DEV02 | I16: #REF! | J16: 2 | K16: 2024 | L16: 45323 | M16: 45351 | N16: 16 | O16: =N16/16 -> 1 | P16: =ROUND(IF(S16="ODC",1*O16,I16*O16),3) -> 1 | Q16: 0.90625 | S16: ODC | T16: BU05,VTCC,DMP | U16: =IF(AND(Q16>=1,S16="ODC"),P16,Q16) -> 0.90625 | V16: =ROUND(SUMIF($B:$B,B16,P:P),3) -> 1 | W16: =ROUND(SUMIF($B:$B,B16,U:U),3) -> 0.906 | X16: =ROUND(W16/V16,2) -> 0.91 | Z16: =COUNTIF($B:$B,B16) -> 1
A17: 6 | B17: 434700 | C17: Hoàng Minh Hiếu | D17: hieuhm12@viettel,com,vn | E17: BU05 - Viễn thông | F17: DEV | G17: J+ | H17: DEV03 | I17: #REF! | J17: 2 | K17: 2024 | L17: 45323 | M17: 45351 | N17: 16 | O17: =N17/16 -> 1 | P17: =ROUND(IF(S17="ODC",1*O17,I17*O17),3) -> 1 | Q17: 1 | S17: ODC | T17: BU05,VTCC,DMP | U17: =IF(AND(Q17>=1,S17="ODC"),P17,Q17) -> 1 | V17: =ROUND(SUMIF($B:$B,B17,P:P),3) -> 1 | W17: =ROUND(SUMIF($B:$B,B17,U:U),3) -> 1 | X17: =ROUND(W17/V17,2) -> 1 | Z17: =COUNTIF($B:$B,B17) -> 1
A18: 7 | B18: 292224 | C18: Lê Quang Duy | D18: duylq12@viettel,com,vn | E18: BU05 - Viễn thông | F18: DEV | G18: M | H18: DEV04 | I18: #REF! | J18: 2 | K18: 2024 | L18: 45323 | M18: 45351 | N18: 16 | O18: =N18/16 -> 1 | P18: =ROUND(IF(S18="ODC",1*O18,I18*O18),3) -> 1 | Q18: 1 | S18: ODC | T18: BU05,VTCC,DMP | U18: =IF(AND(Q18>=1,S18="ODC"),P18,Q18) -> 1 | V18: =ROUND(SUMIF($B:$B,B18,P:P),3) -> 1 | W18: =ROUND(SUMIF($B:$B,B18,U:U),3) -> 1 | X18: =ROUND(W18/V18,2) -> 1 | Z18: =COUNTIF($B:$B,B18) -> 1
A19: 8 | B19: 434397 | C19: Lê Thị Ngọc Huệ | D19: hueltn1@viettel,com,vn | E19: BU05 - Viễn thông | F19: BA | G19: M | H19: BA04 | I19: #REF! | J19: 2 | K19: 2024 | L19: 45323 | M19: 45351 | N19: 16 | O19: =N19/16 -> 1 | P19: =ROUND(IF(S19="ODC",1*O19,I19*O19),3) -> 1 | Q19: 1 | S19: ODC | T19: BU05,VTCC,DMP | U19: =IF(AND(Q19>=1,S19="ODC"),P19,Q19) -> 1 | V19: =ROUND(SUMIF($B:$B,B19,P:P),3) -> 1 | W19: =ROUND(SUMIF($B:$B,B19,U:U),3) -> 1 | X19: =ROUND(W19/V19,2) -> 1 | Z19: =COUNTIF($B:$B,B19) -> 1
A20: 9 | B20: 430051 | C20: Lê Văn Huân | D20: huanlv13@viettel,com,vn | E20: BU05 - Viễn thông | F20: DEV | G20: J+ | H20: DEV03 | I20: #REF! | J20: 2 | K20: 2024 | L20: 45323 | M20: 45351 | N20: 16 | O20: =N20/16 -> 1 | P20: =ROUND(IF(S20="ODC",1*O20,I20*O20),3) -> 1 | Q20: 0.84375 | S20: ODC | T20: BU05,VTCC,DMP | U20: =IF(AND(Q20>=1,S20="ODC"),P20,Q20) -> 0.84375 | V20: =ROUND(SUMIF($B:$B,B20,P:P),3) -> 1 | W20: =ROUND(SUMIF($B:$B,B20,U:U),3) -> 0.844 | X20: =ROUND(W20/V20,2) -> 0.84 | Z20: =COUNTIF($B:$B,B20) -> 1
A21: 10 | B21: 450263 | C21: Nghiêm Thị Hương Ly | D21: LYNTH14@VIETTEL,COM,VN | E21: BU05 - Viễn thông | F21: BA | G21: F | H21: BA01 | I21: #REF! | J21: 2 | K21: 2024 | L21: 45323 | M21: 45351 | N21: 16 | O21: =N21/16 -> 1 | P21: =ROUND(IF(S21="ODC",1*O21,I21*O21),3) -> 1 | Q21: 0.9375 | S21: ODC | T21: BU05,VTCC,DMP | U21: =IF(AND(Q21>=1,S21="ODC"),P21,Q21) -> 0.9375 | V21: =ROUND(SUMIF($B:$B,B21,P:P),3) -> 1 | W21: =ROUND(SUMIF($B:$B,B21,U:U),3) -> 0.938 | X21: =ROUND(W21/V21,2) -> 0.94 | Z21: =COUNTIF($B:$B,B21) -> 1
A22: 11 | B22: 291448 | C22: Nguyễn Gia Đăng | D22: dangng@viettel,com,vn | E22: BU05 - Viễn thông | F22: DEV | G22: M | H22: DEV04 | I22: #REF! | J22: 2 | K22: 2024 | L22: 45323 | M22: 45351 | N22: 16 | O22: =N22/16 -> 1 | P22: =ROUND(IF(S22="ODC",1*O22,I22*O22),3) -> 1 | Q22: 1 | S22: ODC | T22: BU05,VTCC,DMP | U22: =IF(AND(Q22>=1,S22="ODC"),P22,Q22) -> 1 | V22: =ROUND(SUMIF($B:$B,B22,P:P),3) -> 1 | W22: =ROUND(SUMIF($B:$B,B22,U:U),3) -> 1 | X22: =ROUND(W22/V22,2) -> 1 | Z22: =COUNTIF($B:$B,B22) -> 1
A23: 12 | B23: 447269 | C23: Nguyễn Việt Cường | D23: CUONGNV564@VIETTEL,COM,VN | E23: BU05 - Viễn thông | F23: DEV | G23: F | H23: DEV01 | I23: #REF! | J23: 2 | K23: 2024 | L23: 45323 | M23: 45351 | N23: 16 | O23: =N23/16 -> 1 | P23: =ROUND(IF(S23="ODC",1*O23,I23*O23),3) -> 1 | Q23: 1 | S23: ODC | T23: BU05,VTCC,DMP | U23: =IF(AND(Q23>=1,S23="ODC"),P23,Q23) -> 1 | V23: =ROUND(SUMIF($B:$B,B23,P:P),3) -> 1 | W23: =ROUND(SUMIF($B:$B,B23,U:U),3) -> 1 | X23: =ROUND(W23/V23,2) -> 1 | Z23: =COUNTIF($B:$B,B23) -> 1
A24: 13 | B24: 291971 | C24: Phạm Đăng Đô | D24: dopd@viettel,com,vn | E24: BU05 - Viễn thông | F24: DEV | G24: M+ | H24: DEV05 | I24: #REF! | J24: 2 | K24: 2024 | L24: 45323 | M24: 45351 | N24: 16 | O24: =N24/16 -> 1 | P24: =ROUND(IF(S24="ODC",1*O24,I24*O24),3) -> 1 | Q24: 0.875 | S24: ODC | T24: BU05,VTCC,DMP | U24: =IF(AND(Q24>=1,S24="ODC"),P24,Q24) -> 0.875 | V24: =ROUND(SUMIF($B:$B,B24,P:P),3) -> 1 | W24: =ROUND(SUMIF($B:$B,B24,U:U),3) -> 0.875 | X24: =ROUND(W24/V24,2) -> 0.88 | Z24: =COUNTIF($B:$B,B24) -> 1
A25: 14 | B25: 441051 | C25: Phạm Thúy Quỳnh | D25: quynhpt15@viettel,com,vn | E25: BU05 - Viễn thông | F25: DEV | G25: M | H25: DEV04 | I25: #REF! | J25: 2 | K25: 2024 | L25: 45323 | M25: 45351 | N25: 16 | O25: =N25/16 -> 1 | P25: =ROUND(IF(S25="ODC",1*O25,I25*O25),3) -> 1 | Q25: 0.8751 | S25: ODC | T25: BU05,VTCC,DMP | U25: =IF(AND(Q25>=1,S25="ODC"),P25,Q25) -> 0.8751 | V25: =ROUND(SUMIF($B:$B,B25,P:P),3) -> 1 | W25: =ROUND(SUMIF($B:$B,B25,U:U),3) -> 0.875 | X25: =ROUND(W25/V25,2) -> 0.88 | Z25: =COUNTIF($B:$B,B25) -> 1
A26: 15 | B26: 280784 | C26: Phan Chính Quân | D26: QUANPC2@VIETTEL,COM,VN | E26: BU05 - Viễn thông | F26: DEV | G26: M | H26: DEV04 | I26: #REF! | J26: 2 | K26: 2024 | L26: 45323 | M26: 45351 | N26: 16 | O26: =N26/16 -> 1 | P26: =ROUND(IF(S26="ODC",1*O26,I26*O26),3) -> 1 | Q26: 1 | S26: ODC | T26: BU05,VTCC,DMP | U26: =IF(AND(Q26>=1,S26="ODC"),P26,Q26) -> 1 | V26: =ROUND(SUMIF($B:$B,B26,P:P),3) -> 1 | W26: =ROUND(SUMIF($B:$B,B26,U:U),3) -> 1 | X26: =ROUND(W26/V26,2) -> 1 | Z26: =COUNTIF($B:$B,B26) -> 1
A27: 16 | B27: 292225 | C27: Đàm Quang Hiếu | D27: hieudq7@viettel,com,vn | E27: Phòng Quản lý dự án (PMO) | F27: PM | G27: junior | H27: PM02 | I27: #REF! | J27: 2 | K27: 2024 | L27: 45323 | M27: 45351 | N27: =0.15*16 -> 2.4 | O27: 0.15 | P27: =ROUND(IF(S27="ODC",1*O27,I27*O27),3) -> 0.15 | Q27: 0.2 | S27: ODC | T27: BU05,VTCC,DMP | U27: =IF(AND(Q27>=1,S27="ODC"),P27,Q27) -> 0.2 | V27: =ROUND(SUMIF($B:$B,B27,P:P),3) -> #VALUE! | W27: =ROUND(SUMIF($B:$B,B27,U:U),3) -> 1.25 | X27: =ROUND(W27/V27,2) -> #VALUE! | Z27: =COUNTIF($B:$B,B27) -> 5
A28: 17 | B28: 431982 | C28: Đặng Anh Tú | D28: tuda15@viettel,com,vn | E28: BU05 - Viễn thông | F28: DEV | G28: J+ | H28: DEV03 | I28: #REF! | J28: 2 | K28: 2024 | L28: 45323 | M28: 45351 | N28: 16 | O28: =N28/16 -> 1 | P28: =ROUND(IF(S28="ODC",1*O28,I28*O28),3) -> 1 | Q28: 0.9063 | S28: ODC | T28: BU05,VTCC,NNTN | U28: =IF(AND(Q28>=1,S28="ODC"),P28,Q28) -> 0.9063 | V28: =ROUND(SUMIF($B:$B,B28,P:P),3) -> 1 | W28: =ROUND(SUMIF($B:$B,B28,U:U),3) -> 0.906 | X28: =ROUND(W28/V28,2) -> 0.91 | Z28: =COUNTIF($B:$B,B28) -> 1
A29: 18 | B29: 292735 | C29: Hoàng Thanh Sơn | D29: sonht19@viettel,com,vn | E29: BU05 - Viễn thông | F29: DEV | G29: J+ | H29: DEV03 | I29: #REF! | J29: 2 | K29: 2024 | L29: 45323 | M29: 45351 | N29: 16 | O29: =N29/16 -> 1 | P29: =ROUND(IF(S29="ODC",1*O29,I29*O29),3) -> 1 | Q29: 1 | S29: ODC | T29: BU05,VTCC,NNTN | U29: =IF(AND(Q29>=1,S29="ODC"),P29,Q29) -> 1 | V29: =ROUND(SUMIF($B:$B,B29,P:P),3) -> 1 | W29: =ROUND(SUMIF($B:$B,B29,U:U),3) -> 1 | X29: =ROUND(W29/V29,2) -> 1 | Z29: =COUNTIF($B:$B,B29) -> 1
A30: 19 | B30: 440480 | C30: Lê Phi Hùng | D30: hunglp9@viettel,com,vn | E30: BU05 - Viễn thông | F30: DEV | G30: J+ | H30: DEV03 | I30: #REF! | J30: 2 | K30: 2024 | L30: 45323 | M30: 45351 | N30: 16 | O30: =N30/16 -> 1 | P30: =ROUND(IF(S30="ODC",1*O30,I30*O30),3) -> 1 | Q30: 1 | S30: ODC | T30: BU05,VTCC,NNTN | U30: =IF(AND(Q30>=1,S30="ODC"),P30,Q30) -> 1 | V30: =ROUND(SUMIF($B:$B,B30,P:P),3) -> 1 | W30: =ROUND(SUMIF($B:$B,B30,U:U),3) -> 1 | X30: =ROUND(W30/V30,2) -> 1 | Z30: =COUNTIF($B:$B,B30) -> 1
A31: 20 | B31: 454819 | C31: Lê Thành Tâm | D31: TAMLT37@VIETTEL,COM,VN | E31: BU05 - Viễn thông | F31: DEV | G31: J | H31: DEV02 | I31: #REF! | J31: 2 | K31: 2024 | L31: 45323 | M31: 45351 | N31: 16 | O31: =N31/16 -> 1 | P31: =ROUND(IF(S31="ODC",1*O31,I31*O31),3) -> 1 | Q31: 0.8438 | S31: ODC | T31: BU05,VTCC,NNTN | U31: =IF(AND(Q31>=1,S31="ODC"),P31,Q31) -> 0.8438 | V31: =ROUND(SUMIF($B:$B,B31,P:P),3) -> 1 | W31: =ROUND(SUMIF($B:$B,B31,U:U),3) -> 0.844 | X31: =ROUND(W31/V31,2) -> 0.84 | Z31: =COUNTIF($B:$B,B31) -> 1
A32: 21 | B32: 432138 | C32: Nguyễn Văn Đồi | D32: doinv1@viettel,com,vn | E32: BU05 - Viễn thông | F32: DEV | G32: M | H32: DEV04 | I32: #REF! | J32: 2 | K32: 2024 | L32: 45323 | M32: 45351 | N32: 16 | O32: =N32/16 -> 1 | P32: =ROUND(IF(S32="ODC",1*O32,I32*O32),3) -> 1 | Q32: 1 | S32: ODC | T32: BU05,VTCC,NNTN | U32: =IF(AND(Q32>=1,S32="ODC"),P32,Q32) -> 1 | V32: =ROUND(SUMIF($B:$B,B32,P:P),3) -> 1 | W32: =ROUND(SUMIF($B:$B,B32,U:U),3) -> 1 | X32: =ROUND(W32/V32,2) -> 1 | Z32: =COUNTIF($B:$B,B32) -> 1
A33: 22 | B33: 457039 | C33: Nguyễn Văn Nghiệp | D33: NGHIEPNV3@VIETTEL,COM,VN | E33: BU05 - Viễn thông | F33: DEV | G33: J+ | H33: DEV03 | I33: #REF! | J33: 2 | K33: 2024 | L33: 45323 | M33: 45351 | N33: 16 | O33: =N33/16 -> 1 | P33: =ROUND(IF(S33="ODC",1*O33,I33*O33),3) -> 1 | Q33: 1 | S33: ODC | T33: BU05,VTCC,NNTN | U33: =IF(AND(Q33>=1,S33="ODC"),P33,Q33) -> 1 | V33: =ROUND(SUMIF($B:$B,B33,P:P),3) -> 1 | W33: =ROUND(SUMIF($B:$B,B33,U:U),3) -> 1 | X33: =ROUND(W33/V33,2) -> 1 | Z33: =COUNTIF($B:$B,B33) -> 1
A34: 23 | B34: 458699 | C34: Nguyễn Xuân Lộc | D34: locnx7@viettel,com,vn | E34: BU05 - Viễn thông | F34: Dev | G34: J | H34: Dev02 | I34: #REF! | J34: 2 | K34: 2024 | L34: 45323 | M34: 45351 | N34: 16 | O34: =N34/16 -> 1 | P34: =ROUND(IF(S34="ODC",1*O34,I34*O34),3) -> 1 | Q34: 0.9375 | S34: ODC | T34: BU05,VTCC,NNTN | U34: =IF(AND(Q34>=1,S34="ODC"),P34,Q34) -> 0.9375 | V34: =ROUND(SUMIF($B:$B,B34,P:P),3) -> 1 | W34: =ROUND(SUMIF($B:$B,B34,U:U),3) -> 0.938 | X34: =ROUND(W34/V34,2) -> 0.94 | Z34: =COUNTIF($B:$B,B34) -> 1
A35: 24 | B35: 430417 | C35: Phạm Văn Oánh | D35: oanhpv@viettel,com,vn | E35: BU05 - Viễn thông | F35: DEV | G35: M | H35: DEV04 | I35: #REF! | J35: 2 | K35: 2024 | L35: 45323 | M35: 45351 | N35: 16 | O35: =N35/16 -> 1 | P35: =ROUND(IF(S35="ODC",1*O35,I35*O35),3) -> 1 | Q35: 1 | S35: ODC | T35: BU05,VTCC,NNTN | U35: =IF(AND(Q35>=1,S35="ODC"),P35,Q35) -> 1 | V35: =ROUND(SUMIF($B:$B,B35,P:P),3) -> 1 | W35: =ROUND(SUMIF($B:$B,B35,U:U),3) -> 1 | X35: =ROUND(W35/V35,2) -> 1 | Z35: =COUNTIF($B:$B,B35) -> 1
A36: 25 | B36: 448599 | C36: Phí Đức Huy | D36: HUYPD8@VIETTEL,COM,VN | E36: BU05 - Viễn thông | F36: DEV | G36: J | H36: DEV02 | I36: #REF! | J36: 2 | K36: 2024 | L36: 45323 | M36: 45351 | N36: 16 | O36: =N36/16 -> 1 | P36: =ROUND(IF(S36="ODC",1*O36,I36*O36),3) -> 1 | Q36: 1 | S36: ODC | T36: BU05,VTCC,NNTN | U36: =IF(AND(Q36>=1,S36="ODC"),P36,Q36) -> 1 | V36: =ROUND(SUMIF($B:$B,B36,P:P),3) -> 1 | W36: =ROUND(SUMIF($B:$B,B36,U:U),3) -> 1 | X36: =ROUND(W36/V36,2) -> 1 | Z36: =COUNTIF($B:$B,B36) -> 1
A37: 26 | B37: 453665 | C37: Trần Duy Tùng | D37: TUNGTD18@VIETTEL,COM,VN | E37: BU05 - Viễn thông | F37: DEV | G37: J | H37: DEV02 | I37: #REF! | J37: 2 | K37: 2024 | L37: 45323 | M37: 45351 | N37: 16 | O37: =N37/16 -> 1 | P37: =ROUND(IF(S37="ODC",1*O37,I37*O37),3) -> 1 | Q37: 0.9688 | S37: ODC | T37: BU05,VTCC,NNTN | U37: =IF(AND(Q37>=1,S37="ODC"),P37,Q37) -> 0.9688 | V37: =ROUND(SUMIF($B:$B,B37,P:P),3) -> 1 | W37: =ROUND(SUMIF($B:$B,B37,U:U),3) -> 0.969 | X37: =ROUND(W37/V37,2) -> 0.97 | Z37: =COUNTIF($B:$B,B37) -> 1
A38: 27 | B38: 448397 | C38: Trần Ngọc Hùng | D38: HUNGTN24@VIETTEL,COM,VN | E38: BU05 - Viễn thông | F38: DEV | G38: J+ | H38: DEV03 | I38: #REF! | J38: 2 | K38: 2024 | L38: 45323 | M38: 45351 | N38: 16 | O38: =N38/16 -> 1 | P38: =ROUND(IF(S38="ODC",1*O38,I38*O38),3) -> 1 | Q38: 1 | S38: ODC | T38: BU05,VTCC,NNTN | U38: =IF(AND(Q38>=1,S38="ODC"),P38,Q38) -> 1 | V38: =ROUND(SUMIF($B:$B,B38,P:P),3) -> 1 | W38: =ROUND(SUMIF($B:$B,B38,U:U),3) -> 1 | X38: =ROUND(W38/V38,2) -> 1 | Z38: =COUNTIF($B:$B,B38) -> 1
A39: 28 | B39: 453935 | C39: Trần Quang Vịnh | D39: VINHTQ26@VIETTEL,COM,VN | E39: BU05 - Viễn thông | F39: DEV | G39: J | H39: DEV02 | I39: #REF! | J39: 2 | K39: 2024 | L39: 45323 | M39: 45351 | N39: 16 | O39: =N39/16 -> 1 | P39: =ROUND(IF(S39="ODC",1*O39,I39*O39),3) -> 1 | Q39: 0.875 | S39: ODC | T39: BU05,VTCC,NNTN | U39: =IF(AND(Q39>=1,S39="ODC"),P39,Q39) -> 0.875 | V39: =ROUND(SUMIF($B:$B,B39,P:P),3) -> 1 | W39: =ROUND(SUMIF($B:$B,B39,U:U),3) -> 0.875 | X39: =ROUND(W39/V39,2) -> 0.88 | Z39: =COUNTIF($B:$B,B39) -> 1
